2020-06-10 19:01:31,984--__main__--ERROR : ERROR: Unsupported URL: https://nl.hideproxy.me/index.php
Traceback (most recent call last):
  File "C:\Users\Gloryness\AppData\Local\Programs\Python\Python38\lib\site-packages\youtube_dl\YoutubeDL.py", line 797, in extract_info
    ie_result = ie.extract(url)
  File "C:\Users\Gloryness\AppData\Local\Programs\Python\Python38\lib\site-packages\youtube_dl\extractor\common.py", line 530, in extract
    ie_result = self._real_extract(url)
  File "C:\Users\Gloryness\AppData\Local\Programs\Python\Python38\lib\site-packages\youtube_dl\extractor\generic.py", line 3370, in _real_extract
    raise UnsupportedError(url)
youtube_dl.utils.UnsupportedError: Unsupported URL: https://nl.hideproxy.me/index.php
2020-06-10 19:01:31,984--__main__--ERROR : ERROR: Unsupported URL: https://nl.hideproxy.me/index.php
Traceback (most recent call last):
  File "C:\Users\Gloryness\AppData\Local\Programs\Python\Python38\lib\site-packages\youtube_dl\YoutubeDL.py", line 797, in extract_info
    ie_result = ie.extract(url)
  File "C:\Users\Gloryness\AppData\Local\Programs\Python\Python38\lib\site-packages\youtube_dl\extractor\common.py", line 530, in extract
    ie_result = self._real_extract(url)
  File "C:\Users\Gloryness\AppData\Local\Programs\Python\Python38\lib\site-packages\youtube_dl\extractor\generic.py", line 3370, in _real_extract
    raise UnsupportedError(url)
youtube_dl.utils.UnsupportedError: Unsupported URL: https://nl.hideproxy.me/index.php
2020-06-10 19:01:32,021--__main__--
https://nl.hideproxy.me/go.php?u=GSoE%2FefR9AiJghLlQCF5UV2Rtuv63CFsNQADdb%2BpnSVR93QZcAB2J%2B6yINZcCxVkqt7Eid0aptRMxg%3D%3D&b=29 was unable to convert to mkv due to no available formats otherwise an unknown error.
Traceback (most recent call last):
  File "C:\Users\Gloryness\AppData\Local\Programs\Python\Python38\lib\site-packages\youtube_dl\YoutubeDL.py", line 797, in extract_info
    ie_result = ie.extract(url)
  File "C:\Users\Gloryness\AppData\Local\Programs\Python\Python38\lib\site-packages\youtube_dl\extractor\common.py", line 530, in extract
    ie_result = self._real_extract(url)
  File "C:\Users\Gloryness\AppData\Local\Programs\Python\Python38\lib\site-packages\youtube_dl\extractor\generic.py", line 3370, in _real_extract
    raise UnsupportedError(url)
youtube_dl.utils.UnsupportedError: Unsupported URL: https://nl.hideproxy.me/index.php

During handling of the above exception, another exception occurred:

Traceback (most recent call last):
  File "C:\Users\Gloryness\AppData\Local\Programs\Python\Python38\lib\logging\__init__.py", line 1084, in emit
    stream.write(msg + self.terminator)
AttributeError: 'NoneType' object has no attribute 'write'

During handling of the above exception, another exception occurred:

Traceback (most recent call last):
  File "R:\# Python 3.8\Python Saves\Projects\Connections\Youtube-DL GUI\main.py", line 2369, in Download
    ydl.download([_url_holder])
  File "C:\Users\Gloryness\AppData\Local\Programs\Python\Python38\lib\site-packages\youtube_dl\YoutubeDL.py", line 2018, in download
    res = self.extract_info(
  File "C:\Users\Gloryness\AppData\Local\Programs\Python\Python38\lib\site-packages\youtube_dl\YoutubeDL.py", line 808, in extract_info
    return self.process_ie_result(ie_result, download, extra_info)
  File "C:\Users\Gloryness\AppData\Local\Programs\Python\Python38\lib\site-packages\youtube_dl\YoutubeDL.py", line 867, in process_ie_result
    return self.extract_info(ie_result['url'],
  File "C:\Users\Gloryness\AppData\Local\Programs\Python\Python38\lib\site-packages\youtube_dl\YoutubeDL.py", line 820, in extract_info
    self.report_error(compat_str(e), e.format_traceback())
  File "C:\Users\Gloryness\AppData\Local\Programs\Python\Python38\lib\site-packages\youtube_dl\YoutubeDL.py", line 625, in report_error
    self.trouble(error_message, tb)
  File "C:\Users\Gloryness\AppData\Local\Programs\Python\Python38\lib\site-packages\youtube_dl\YoutubeDL.py", line 578, in trouble
    self.to_stderr(message)
  File "C:\Users\Gloryness\AppData\Local\Programs\Python\Python38\lib\site-packages\youtube_dl\YoutubeDL.py", line 523, in to_stderr
    self.params['logger'].error(message)
  File "R:\# Python 3.8\Python Saves\Projects\Connections\Youtube-DL GUI\main.py", line 2939, in error
    logger.exception(msg="ERROR : {}".format(msg))
  File "C:\Users\Gloryness\AppData\Local\Programs\Python\Python38\lib\logging\__init__.py", line 1469, in exception
    self.error(msg, *args, exc_info=exc_info, **kwargs)
  File "C:\Users\Gloryness\AppData\Local\Programs\Python\Python38\lib\logging\__init__.py", line 1463, in error
    self._log(ERROR, msg, args, **kwargs)
  File "C:\Users\Gloryness\AppData\Local\Programs\Python\Python38\lib\logging\__init__.py", line 1577, in _log
    self.handle(record)
  File "C:\Users\Gloryness\AppData\Local\Programs\Python\Python38\lib\logging\__init__.py", line 1587, in handle
    self.callHandlers(record)
  File "C:\Users\Gloryness\AppData\Local\Programs\Python\Python38\lib\logging\__init__.py", line 1649, in callHandlers
    hdlr.handle(record)
  File "C:\Users\Gloryness\AppData\Local\Programs\Python\Python38\lib\logging\__init__.py", line 950, in handle
    self.emit(record)
  File "C:\Users\Gloryness\AppData\Local\Programs\Python\Python38\lib\logging\__init__.py", line 1089, in emit
    self.handleError(record)
  File "C:\Users\Gloryness\AppData\Local\Programs\Python\Python38\lib\logging\__init__.py", line 1002, in handleError
    sys.stderr.write('--- Logging error ---\n')
  File "R:\# Python 3.8\Python Saves\Projects\Connections\Youtube-DL GUI\main.py", line 2145, in write
    self.output.config(state=NORMAL)
AttributeError: 'NoneType' object has no attribute 'config'
2020-06-10 19:01:32,021--__main__--
https://nl.hideproxy.me/go.php?u=GSoE%2FefR9AiJghLlQCF5UV2Rtuv63CFsNQADdb%2BpnSVR93QZcAB2J%2B6yINZcCxVkqt7Eid0aptRMxg%3D%3D&b=29 was unable to convert to mkv due to no available formats otherwise an unknown error.
Traceback (most recent call last):
  File "C:\Users\Gloryness\AppData\Local\Programs\Python\Python38\lib\site-packages\youtube_dl\YoutubeDL.py", line 797, in extract_info
    ie_result = ie.extract(url)
  File "C:\Users\Gloryness\AppData\Local\Programs\Python\Python38\lib\site-packages\youtube_dl\extractor\common.py", line 530, in extract
    ie_result = self._real_extract(url)
  File "C:\Users\Gloryness\AppData\Local\Programs\Python\Python38\lib\site-packages\youtube_dl\extractor\generic.py", line 3370, in _real_extract
    raise UnsupportedError(url)
youtube_dl.utils.UnsupportedError: Unsupported URL: https://nl.hideproxy.me/index.php

During handling of the above exception, another exception occurred:

Traceback (most recent call last):
  File "C:\Users\Gloryness\AppData\Local\Programs\Python\Python38\lib\logging\__init__.py", line 1084, in emit
    stream.write(msg + self.terminator)
AttributeError: 'NoneType' object has no attribute 'write'

During handling of the above exception, another exception occurred:

Traceback (most recent call last):
  File "R:\# Python 3.8\Python Saves\Projects\Connections\Youtube-DL GUI\main.py", line 2369, in Download
    ydl.download([_url_holder])
  File "C:\Users\Gloryness\AppData\Local\Programs\Python\Python38\lib\site-packages\youtube_dl\YoutubeDL.py", line 2018, in download
    res = self.extract_info(
  File "C:\Users\Gloryness\AppData\Local\Programs\Python\Python38\lib\site-packages\youtube_dl\YoutubeDL.py", line 808, in extract_info
    return self.process_ie_result(ie_result, download, extra_info)
  File "C:\Users\Gloryness\AppData\Local\Programs\Python\Python38\lib\site-packages\youtube_dl\YoutubeDL.py", line 867, in process_ie_result
    return self.extract_info(ie_result['url'],
  File "C:\Users\Gloryness\AppData\Local\Programs\Python\Python38\lib\site-packages\youtube_dl\YoutubeDL.py", line 820, in extract_info
    self.report_error(compat_str(e), e.format_traceback())
  File "C:\Users\Gloryness\AppData\Local\Programs\Python\Python38\lib\site-packages\youtube_dl\YoutubeDL.py", line 625, in report_error
    self.trouble(error_message, tb)
  File "C:\Users\Gloryness\AppData\Local\Programs\Python\Python38\lib\site-packages\youtube_dl\YoutubeDL.py", line 578, in trouble
    self.to_stderr(message)
  File "C:\Users\Gloryness\AppData\Local\Programs\Python\Python38\lib\site-packages\youtube_dl\YoutubeDL.py", line 523, in to_stderr
    self.params['logger'].error(message)
  File "R:\# Python 3.8\Python Saves\Projects\Connections\Youtube-DL GUI\main.py", line 2939, in error
    logger.exception(msg="ERROR : {}".format(msg))
  File "C:\Users\Gloryness\AppData\Local\Programs\Python\Python38\lib\logging\__init__.py", line 1469, in exception
    self.error(msg, *args, exc_info=exc_info, **kwargs)
  File "C:\Users\Gloryness\AppData\Local\Programs\Python\Python38\lib\logging\__init__.py", line 1463, in error
    self._log(ERROR, msg, args, **kwargs)
  File "C:\Users\Gloryness\AppData\Local\Programs\Python\Python38\lib\logging\__init__.py", line 1577, in _log
    self.handle(record)
  File "C:\Users\Gloryness\AppData\Local\Programs\Python\Python38\lib\logging\__init__.py", line 1587, in handle
    self.callHandlers(record)
  File "C:\Users\Gloryness\AppData\Local\Programs\Python\Python38\lib\logging\__init__.py", line 1649, in callHandlers
    hdlr.handle(record)
  File "C:\Users\Gloryness\AppData\Local\Programs\Python\Python38\lib\logging\__init__.py", line 950, in handle
    self.emit(record)
  File "C:\Users\Gloryness\AppData\Local\Programs\Python\Python38\lib\logging\__init__.py", line 1089, in emit
    self.handleError(record)
  File "C:\Users\Gloryness\AppData\Local\Programs\Python\Python38\lib\logging\__init__.py", line 1002, in handleError
    sys.stderr.write('--- Logging error ---\n')
  File "R:\# Python 3.8\Python Saves\Projects\Connections\Youtube-DL GUI\main.py", line 2145, in write
    self.output.config(state=NORMAL)
AttributeError: 'NoneType' object has no attribute 'config'
2020-06-10 19:04:27,704--__main__--
https://www.pornhub.com/view_video.php?viewkey=ph5ec4a56421994 was unable to convert to mkv due to no available formats otherwise an unknown error.
Traceback (most recent call last):
  File "C:\Users\Gloryness\AppData\Local\Programs\Python\Python38\lib\urllib\request.py", line 1319, in do_open
    h.request(req.get_method(), req.selector, req.data, headers,
  File "C:\Users\Gloryness\AppData\Local\Programs\Python\Python38\lib\http\client.py", line 1230, in request
    self._send_request(method, url, body, headers, encode_chunked)
  File "C:\Users\Gloryness\AppData\Local\Programs\Python\Python38\lib\http\client.py", line 1276, in _send_request
    self.endheaders(body, encode_chunked=encode_chunked)
  File "C:\Users\Gloryness\AppData\Local\Programs\Python\Python38\lib\http\client.py", line 1225, in endheaders
    self._send_output(message_body, encode_chunked=encode_chunked)
  File "C:\Users\Gloryness\AppData\Local\Programs\Python\Python38\lib\http\client.py", line 1004, in _send_output
    self.send(msg)
  File "C:\Users\Gloryness\AppData\Local\Programs\Python\Python38\lib\http\client.py", line 944, in send
    self.connect()
  File "C:\Users\Gloryness\AppData\Local\Programs\Python\Python38\lib\http\client.py", line 1392, in connect
    super().connect()
  File "C:\Users\Gloryness\AppData\Local\Programs\Python\Python38\lib\http\client.py", line 915, in connect
    self.sock = self._create_connection(
  File "C:\Users\Gloryness\AppData\Local\Programs\Python\Python38\lib\socket.py", line 808, in create_connection
    raise err
  File "C:\Users\Gloryness\AppData\Local\Programs\Python\Python38\lib\socket.py", line 796, in create_connection
    sock.connect(sa)
TimeoutError: [WinError 10060] A connection attempt failed because the connected party did not properly respond after a period of time, or established connection failed because connected host has failed to respond

During handling of the above exception, another exception occurred:

Traceback (most recent call last):
  File "C:\Users\Gloryness\AppData\Local\Programs\Python\Python38\lib\site-packages\youtube_dl\extractor\common.py", line 627, in _request_webpage
    return self._downloader.urlopen(url_or_request)
  File "C:\Users\Gloryness\AppData\Local\Programs\Python\Python38\lib\site-packages\youtube_dl\YoutubeDL.py", line 2238, in urlopen
    return self._opener.open(req, timeout=self._socket_timeout)
  File "C:\Users\Gloryness\AppData\Local\Programs\Python\Python38\lib\urllib\request.py", line 525, in open
    response = self._open(req, data)
  File "C:\Users\Gloryness\AppData\Local\Programs\Python\Python38\lib\urllib\request.py", line 542, in _open
    result = self._call_chain(self.handle_open, protocol, protocol +
  File "C:\Users\Gloryness\AppData\Local\Programs\Python\Python38\lib\urllib\request.py", line 502, in _call_chain
    result = func(*args)
  File "C:\Users\Gloryness\AppData\Local\Programs\Python\Python38\lib\site-packages\youtube_dl\utils.py", line 2734, in https_open
    return self.do_open(functools.partial(
  File "C:\Users\Gloryness\AppData\Local\Programs\Python\Python38\lib\urllib\request.py", line 1322, in do_open
    raise URLError(err)
urllib.error.URLError: <urlopen error [WinError 10060] A connection attempt failed because the connected party did not properly respond after a period of time, or established connection failed because connected host has failed to respond>

During handling of the above exception, another exception occurred:

Traceback (most recent call last):
  File "C:\Users\Gloryness\AppData\Local\Programs\Python\Python38\lib\site-packages\youtube_dl\YoutubeDL.py", line 797, in extract_info
    ie_result = ie.extract(url)
  File "C:\Users\Gloryness\AppData\Local\Programs\Python\Python38\lib\site-packages\youtube_dl\extractor\common.py", line 530, in extract
    ie_result = self._real_extract(url)
  File "C:\Users\Gloryness\AppData\Local\Programs\Python\Python38\lib\site-packages\youtube_dl\extractor\pornhub.py", line 187, in _real_extract
    webpage = dl_webpage('pc')
  File "C:\Users\Gloryness\AppData\Local\Programs\Python\Python38\lib\site-packages\youtube_dl\extractor\pornhub.py", line 183, in dl_webpage
    return self._download_webpage(
  File "C:\Users\Gloryness\AppData\Local\Programs\Python\Python38\lib\site-packages\youtube_dl\extractor\common.py", line 791, in _download_webpage
    res = self._download_webpage_handle(
  File "C:\Users\Gloryness\AppData\Local\Programs\Python\Python38\lib\site-packages\youtube_dl\extractor\pornhub.py", line 33, in _download_webpage_handle
    webpage, urlh = dl(*args, **kwargs)
  File "C:\Users\Gloryness\AppData\Local\Programs\Python\Python38\lib\site-packages\youtube_dl\extractor\pornhub.py", line 31, in dl
    return super(PornHubBaseIE, self)._download_webpage_handle(*args, **kwargs)
  File "C:\Users\Gloryness\AppData\Local\Programs\Python\Python38\lib\site-packages\youtube_dl\extractor\common.py", line 660, in _download_webpage_handle
    urlh = self._request_webpage(url_or_request, video_id, note, errnote, fatal, data=data, headers=headers, query=query, expected_status=expected_status)
  File "C:\Users\Gloryness\AppData\Local\Programs\Python\Python38\lib\site-packages\youtube_dl\extractor\common.py", line 645, in _request_webpage
    raise ExtractorError(errmsg, sys.exc_info()[2], cause=err)
youtube_dl.utils.ExtractorError: Unable to download webpage: <urlopen error [WinError 10060] A connection attempt failed because the connected party did not properly respond after a period of time, or established connection failed because connected host has failed to respond> (caused by URLError(TimeoutError(10060, 'A connection attempt failed because the connected party did not properly respond after a period of time, or established connection failed because connected host has failed to respond', None, 10060, None)))

During handling of the above exception, another exception occurred:

Traceback (most recent call last):
  File "R:\# Python 3.8\Python Saves\Projects\Connections\Youtube-DL GUI\main.py", line 2369, in Download
    ydl.download([_url_holder])
  File "C:\Users\Gloryness\AppData\Local\Programs\Python\Python38\lib\site-packages\youtube_dl\YoutubeDL.py", line 2018, in download
    res = self.extract_info(
  File "C:\Users\Gloryness\AppData\Local\Programs\Python\Python38\lib\site-packages\youtube_dl\YoutubeDL.py", line 820, in extract_info
    self.report_error(compat_str(e), e.format_traceback())
  File "C:\Users\Gloryness\AppData\Local\Programs\Python\Python38\lib\site-packages\youtube_dl\YoutubeDL.py", line 625, in report_error
    self.trouble(error_message, tb)
  File "C:\Users\Gloryness\AppData\Local\Programs\Python\Python38\lib\site-packages\youtube_dl\YoutubeDL.py", line 578, in trouble
    self.to_stderr(message)
  File "C:\Users\Gloryness\AppData\Local\Programs\Python\Python38\lib\site-packages\youtube_dl\YoutubeDL.py", line 523, in to_stderr
    self.params['logger'].error(message)
  File "R:\# Python 3.8\Python Saves\Projects\Connections\Youtube-DL GUI\main.py", line 2938, in error
    print(msg)
  File "R:\# Python 3.8\Python Saves\Projects\Connections\Youtube-DL GUI\main.py", line 2145, in write
    self.output.config(state=NORMAL)
  File "C:\Users\Gloryness\AppData\Local\Programs\Python\Python38\lib\tkinter\__init__.py", line 1636, in configure
    return self._configure('configure', cnf, kw)
  File "C:\Users\Gloryness\AppData\Local\Programs\Python\Python38\lib\tkinter\__init__.py", line 1626, in _configure
    self.tk.call(_flatten((self._w, cmd)) + self._options(cnf))
RuntimeError: main thread is not in main loop
2020-06-10 19:04:27,704--__main__--
https://www.pornhub.com/view_video.php?viewkey=ph5ec4a56421994 was unable to convert to mkv due to no available formats otherwise an unknown error.
Traceback (most recent call last):
  File "C:\Users\Gloryness\AppData\Local\Programs\Python\Python38\lib\urllib\request.py", line 1319, in do_open
    h.request(req.get_method(), req.selector, req.data, headers,
  File "C:\Users\Gloryness\AppData\Local\Programs\Python\Python38\lib\http\client.py", line 1230, in request
    self._send_request(method, url, body, headers, encode_chunked)
  File "C:\Users\Gloryness\AppData\Local\Programs\Python\Python38\lib\http\client.py", line 1276, in _send_request
    self.endheaders(body, encode_chunked=encode_chunked)
  File "C:\Users\Gloryness\AppData\Local\Programs\Python\Python38\lib\http\client.py", line 1225, in endheaders
    self._send_output(message_body, encode_chunked=encode_chunked)
  File "C:\Users\Gloryness\AppData\Local\Programs\Python\Python38\lib\http\client.py", line 1004, in _send_output
    self.send(msg)
  File "C:\Users\Gloryness\AppData\Local\Programs\Python\Python38\lib\http\client.py", line 944, in send
    self.connect()
  File "C:\Users\Gloryness\AppData\Local\Programs\Python\Python38\lib\http\client.py", line 1392, in connect
    super().connect()
  File "C:\Users\Gloryness\AppData\Local\Programs\Python\Python38\lib\http\client.py", line 915, in connect
    self.sock = self._create_connection(
  File "C:\Users\Gloryness\AppData\Local\Programs\Python\Python38\lib\socket.py", line 808, in create_connection
    raise err
  File "C:\Users\Gloryness\AppData\Local\Programs\Python\Python38\lib\socket.py", line 796, in create_connection
    sock.connect(sa)
TimeoutError: [WinError 10060] A connection attempt failed because the connected party did not properly respond after a period of time, or established connection failed because connected host has failed to respond

During handling of the above exception, another exception occurred:

Traceback (most recent call last):
  File "C:\Users\Gloryness\AppData\Local\Programs\Python\Python38\lib\site-packages\youtube_dl\extractor\common.py", line 627, in _request_webpage
    return self._downloader.urlopen(url_or_request)
  File "C:\Users\Gloryness\AppData\Local\Programs\Python\Python38\lib\site-packages\youtube_dl\YoutubeDL.py", line 2238, in urlopen
    return self._opener.open(req, timeout=self._socket_timeout)
  File "C:\Users\Gloryness\AppData\Local\Programs\Python\Python38\lib\urllib\request.py", line 525, in open
    response = self._open(req, data)
  File "C:\Users\Gloryness\AppData\Local\Programs\Python\Python38\lib\urllib\request.py", line 542, in _open
    result = self._call_chain(self.handle_open, protocol, protocol +
  File "C:\Users\Gloryness\AppData\Local\Programs\Python\Python38\lib\urllib\request.py", line 502, in _call_chain
    result = func(*args)
  File "C:\Users\Gloryness\AppData\Local\Programs\Python\Python38\lib\site-packages\youtube_dl\utils.py", line 2734, in https_open
    return self.do_open(functools.partial(
  File "C:\Users\Gloryness\AppData\Local\Programs\Python\Python38\lib\urllib\request.py", line 1322, in do_open
    raise URLError(err)
urllib.error.URLError: <urlopen error [WinError 10060] A connection attempt failed because the connected party did not properly respond after a period of time, or established connection failed because connected host has failed to respond>

During handling of the above exception, another exception occurred:

Traceback (most recent call last):
  File "C:\Users\Gloryness\AppData\Local\Programs\Python\Python38\lib\site-packages\youtube_dl\YoutubeDL.py", line 797, in extract_info
    ie_result = ie.extract(url)
  File "C:\Users\Gloryness\AppData\Local\Programs\Python\Python38\lib\site-packages\youtube_dl\extractor\common.py", line 530, in extract
    ie_result = self._real_extract(url)
  File "C:\Users\Gloryness\AppData\Local\Programs\Python\Python38\lib\site-packages\youtube_dl\extractor\pornhub.py", line 187, in _real_extract
    webpage = dl_webpage('pc')
  File "C:\Users\Gloryness\AppData\Local\Programs\Python\Python38\lib\site-packages\youtube_dl\extractor\pornhub.py", line 183, in dl_webpage
    return self._download_webpage(
  File "C:\Users\Gloryness\AppData\Local\Programs\Python\Python38\lib\site-packages\youtube_dl\extractor\common.py", line 791, in _download_webpage
    res = self._download_webpage_handle(
  File "C:\Users\Gloryness\AppData\Local\Programs\Python\Python38\lib\site-packages\youtube_dl\extractor\pornhub.py", line 33, in _download_webpage_handle
    webpage, urlh = dl(*args, **kwargs)
  File "C:\Users\Gloryness\AppData\Local\Programs\Python\Python38\lib\site-packages\youtube_dl\extractor\pornhub.py", line 31, in dl
    return super(PornHubBaseIE, self)._download_webpage_handle(*args, **kwargs)
  File "C:\Users\Gloryness\AppData\Local\Programs\Python\Python38\lib\site-packages\youtube_dl\extractor\common.py", line 660, in _download_webpage_handle
    urlh = self._request_webpage(url_or_request, video_id, note, errnote, fatal, data=data, headers=headers, query=query, expected_status=expected_status)
  File "C:\Users\Gloryness\AppData\Local\Programs\Python\Python38\lib\site-packages\youtube_dl\extractor\common.py", line 645, in _request_webpage
    raise ExtractorError(errmsg, sys.exc_info()[2], cause=err)
youtube_dl.utils.ExtractorError: Unable to download webpage: <urlopen error [WinError 10060] A connection attempt failed because the connected party did not properly respond after a period of time, or established connection failed because connected host has failed to respond> (caused by URLError(TimeoutError(10060, 'A connection attempt failed because the connected party did not properly respond after a period of time, or established connection failed because connected host has failed to respond', None, 10060, None)))

During handling of the above exception, another exception occurred:

Traceback (most recent call last):
  File "R:\# Python 3.8\Python Saves\Projects\Connections\Youtube-DL GUI\main.py", line 2369, in Download
    ydl.download([_url_holder])
  File "C:\Users\Gloryness\AppData\Local\Programs\Python\Python38\lib\site-packages\youtube_dl\YoutubeDL.py", line 2018, in download
    res = self.extract_info(
  File "C:\Users\Gloryness\AppData\Local\Programs\Python\Python38\lib\site-packages\youtube_dl\YoutubeDL.py", line 820, in extract_info
    self.report_error(compat_str(e), e.format_traceback())
  File "C:\Users\Gloryness\AppData\Local\Programs\Python\Python38\lib\site-packages\youtube_dl\YoutubeDL.py", line 625, in report_error
    self.trouble(error_message, tb)
  File "C:\Users\Gloryness\AppData\Local\Programs\Python\Python38\lib\site-packages\youtube_dl\YoutubeDL.py", line 578, in trouble
    self.to_stderr(message)
  File "C:\Users\Gloryness\AppData\Local\Programs\Python\Python38\lib\site-packages\youtube_dl\YoutubeDL.py", line 523, in to_stderr
    self.params['logger'].error(message)
  File "R:\# Python 3.8\Python Saves\Projects\Connections\Youtube-DL GUI\main.py", line 2938, in error
    print(msg)
  File "R:\# Python 3.8\Python Saves\Projects\Connections\Youtube-DL GUI\main.py", line 2145, in write
    self.output.config(state=NORMAL)
  File "C:\Users\Gloryness\AppData\Local\Programs\Python\Python38\lib\tkinter\__init__.py", line 1636, in configure
    return self._configure('configure', cnf, kw)
  File "C:\Users\Gloryness\AppData\Local\Programs\Python\Python38\lib\tkinter\__init__.py", line 1626, in _configure
    self.tk.call(_flatten((self._w, cmd)) + self._options(cnf))
RuntimeError: main thread is not in main loop
